Workbook
Name EventHoles: Admin!$A$2:$A$3
Name TGFChapter: Admin!$B$2:$B$5

Sheet Game Calculator
A1: SIDE GAME CALCULATOR
A2: SAN ANTONIO | J2: AUSTIN
B3: EDIT | K3: EDIT
A4: 9 or 18 | B4: 18 | C4: TOTAL | D4: MWP | J4: 9 or 18 | K4: 18 | L4: TOTAL | M4: MWP
A5: Total Players | B5: 18 | C5: =IF(B4=9,SUM(B5*7),IF(B4=18,SUM(B5*14),"")) -> 252 | D5: =C17 -> 108 | J5: Total Players | L5: =IF(K4=9,SUM(K5*7),IF(K4=18,SUM(K5*14),"")) -> 0 | M5: =L17 -> #N/A
A6: Net Players | B6: 13 | C6: =IF(B4=9,SUM(B6*13),IF(B4=18,SUM(B6*26),"")) -> 338 | D6: =C23 -> 219 | J6: Net Players | L6: =IF(K4=9,SUM(K6*13),IF(K4=18,SUM(K6*26),"")) -> 0 | M6: =L23 -> 0
A7: Gross Players | B7: 9 | C7: =IF(B4=9,SUM(B7*13),IF(B4=18,SUM(B7*26),"")) -> 234 | D7: =C28 -> 117 | J7: Gross Players | L7: =IF(K4=9,SUM(K7*13),IF(K4=18,SUM(K7*26),"")) -> 0 | M7: =L28 -> 0
B8: Total | C8: =SUM(C5:C7) -> 824 | D8: =SUM(D5:D7) -> 444 | K8: Total | L8: =SUM(L5:L7) -> 0 | M8: =SUM(M5:M7) -> #N/A
A10: INCLUDED Games | B10: Prize Fund | C10: MWP | E10: 1st | F10: 2nd | J10: INCLUDED Games | K10: Prize Fund | L10: MWP | N10: 1st | O10: 2nd
A11: =_xlfn.XLOOKUP(B5,'Side Games 9'!C2:BM2,'Side Games 9'!C8:BM8) -> TEAM Net | B11: =IF(B4=9,_xlfn.XLOOKUP(B5,'Side Games 9'!C2:BM2,'Side Games 9'!C4:BM4),IF(B4=18,_xlfn.XLOOKUP(B5,'Side Games 18'!C2:BM2,'Side Games 18'!C4:BM4),"")) -> 144 | C11: =IF(B4=9,_xlfn.XLOOKUP(B5,'Side Games 9'!C2:BM2,'Side Games 9'!C7:BM7),IF(B4=18,_xlfn.XLOOKUP(B5,'Side Games 18'!C2:BM2,'Side Games 18'!C7:BM7),"")) -> 36 | E11: =IF(B4=9,_xlfn.XLOOKUP(B5,'Side Games 9'!C2:BM2,'Side Games 9'!C5:BM5),IF(B4=18,_xlfn.XLOOKUP(B5,'Side Games 18'!C2:BM2,'Side Games 18'!C5:BM5),"")) -> 144 | F11: =IF(B4=9,_xlfn.XLOOKUP(B5,'Side Games 9'!C2:BM2,'Side Games 9'!C6:BM6),IF(B4=18,_xlfn.XLOOKUP(B5,'Side Games 18'!C2:BM2,'Side Games 18'!C6:BM6),"")) -> 0 | J11: =IF(OR(K5="",K5=0),"Team Game",_xlfn.XLOOKUP(K5,'Side Games 9'!C2:BM2,'Side Games 9'!C8:BM8)) -> Team Game | K11: =IF(K4=9,_xlfn.XLOOKUP(K5,'Side Games 9'!C2:BM2,'Side Games 9'!C4:BM4),IF(K4=18,_xlfn.XLOOKUP(K5,'Side Games 18'!C2:BM2,'Side Games 18'!C4:BM4),"")) -> #N/A | L11: =IF(K4=9,_xlfn.XLOOKUP(K5,'Side Games 9'!C2:BM2,'Side Games 9'!C7:BM7),IF(K4=18,_xlfn.XLOOKUP(K5,'Side Games 18'!C2:BM2,'Side Games 18'!C7:BM7),"")) -> #N/A | N11: =IF(K4=9,_xlfn.XLOOKUP(K5,'Side Games 9'!C2:BM2,'Side Games 9'!C5:BM5),IF(K4=18,_xlfn.XLOOKUP(K5,'Side Games 18'!C2:BM2,'Side Games 18'!C5:BM5),"")) -> #N/A | O11: =IF(K4=9,_xlfn.XLOOKUP(K5,'Side Games 9'!C2:BM2,'Side Games 9'!C6:BM6),IF(K4=18,_xlfn.XLOOKUP(K5,'Side Games 18'!C2:BM2,'Side Games 18'!C6:BM6),"")) -> #N/A
A12: Closest to Pin #1 | B12: =IF(AND(B$4=9,NOT(B$5=0)),_xlfn.XLOOKUP(B$5,'Side Games 9'!C$2:BM$2,'Side Games 9'!C10:BM10),IF(AND(B$4=18,NOT(B$5=0)),_xlfn.XLOOKUP(B$5,'Side Games 18'!C$2:BM$2,'Side Games 18'!C10:BM10),"")) -> 36 | C12: =IF(B12=0,"",B12) -> 36 | J12: Closest to Pin #1 | K12: =IF(AND(K$4=9,NOT(K$5=0)),_xlfn.XLOOKUP(K$5,'Side Games 9'!C$2:BM$2,'Side Games 9'!C10:BM10),IF(AND(K$4=18,NOT(K$5=0)),_xlfn.XLOOKUP(K$5,'Side Games 18'!C$2:BM$2,'Side Games 18'!C10:BM10),"")) | L12: =IF(K12=0,"",K12)
A13: Closest to Pin #2 | B13: =IF(AND(B$4=9,NOT(B$5=0)),_xlfn.XLOOKUP(B$5,'Side Games 9'!C$2:BM$2,'Side Games 9'!C11:BM11),IF(AND(B$4=18,NOT(B$5=0)),_xlfn.XLOOKUP(B$5,'Side Games 18'!C$2:BM$2,'Side Games 18'!C11:BM11),"")) -> 36 | C13: =IF(B13=0,"",B13) -> 36 | J13: Closest to Pin #2 | K13: =IF(AND(K$4=9,NOT(K$5=0)),_xlfn.XLOOKUP(K$5,'Side Games 9'!C$2:BM$2,'Side Games 9'!C11:BM11),IF(AND(K$4=18,NOT(K$5=0)),_xlfn.XLOOKUP(K$5,'Side Games 18'!C$2:BM$2,'Side Games 18'!C11:BM11),"")) | L13: =IF(K13=0,"",K13)
A14: Closest to Pin #3 | B14: =IF(AND(B$4=9,NOT(B$5=0)),"Only for 18s",IF(AND(B$4=18,NOT(B$5=0)),_xlfn.XLOOKUP(B$5,'Side Games 18'!C$2:BM$2,'Side Games 18'!C12:BM12),"")) -> No Game | C14: =IF(OR(B14=0,B14="Only for 18s"),"",B14) -> No Game | J14: Closest to Pin #3 | K14: =IF(AND(K$4=9,NOT(K$5=0)),"Only for 18s",IF(AND(K$4=18,NOT(K$5=0)),_xlfn.XLOOKUP(K$5,'Side Games 18'!C$2:BM$2,'Side Games 18'!C12:BM12),"")) | L14: =IF(OR(K14=0,K14="Only for 18s"),"",K14) | V14: MVP | W14: 44
A15: Closest to Pin #4 | B15: =IF(AND(B$4=9,NOT(B$5=0)),"Only for 18s",IF(AND(B$4=18,NOT(B$5=0)),_xlfn.XLOOKUP(B$5,'Side Games 18'!C$2:BM$2,'Side Games 18'!C13:BM13),"")) -> No Game | C15: =IF(OR(B15=0,B15="Only for 18s"),"",B15) -> No Game | J15: Closest to Pin #4 | K15: =IF(AND(K$4=9,NOT(K$5=0)),"Only for 18s",IF(AND(K$4=18,NOT(K$5=0)),_xlfn.XLOOKUP(K$5,'Side Games 18'!C$2:BM$2,'Side Games 18'!C13:BM13),"")) | L15: =IF(OR(K15=0,K15="Only for 18s"),"",K15) | V15: TGF MVP | W15: 80
A16: Hole-In-One | B16: =IF(B4=9,_xlfn.XLOOKUP(B5,'Side Games 9'!C2:BM2,'Side Games 9'!C12:BM12),IF(B4=18,_xlfn.XLOOKUP(B5,'Side Games 18'!C2:BM2,'Side Games 18'!C14:BM14),"")) -> 36 | J16: Hole-In-One | K16: =IF(K4=9,_xlfn.XLOOKUP(K5,'Side Games 9'!C2:BM2,'Side Games 9'!C12:BM12),IF(K4=18,_xlfn.XLOOKUP(K5,'Side Games 18'!C2:BM2,'Side Games 18'!C14:BM14),"")) -> #N/A | V16: NET | W16: 66
A17: Subtotal | B17: =SUM(B11:B16) -> 252 | C17: =SUM(C11:C16) -> 108 | J17: Subtotal | K17: =SUM(K11:K16) -> #N/A | L17: =SUM(L11:L16) -> #N/A | W17: =SUM(W14:W16) -> 190
A19: NET Games | B19: Prize Fund | C19: MWP | D19: Flights | E19: 1st | F19: 2nd | G19: 3rd | H19: 4th | J19: NET Games | K19: Prize Fund | L19: MWP | M19: Flights | N19: 1st | O19: 2nd | P19: 3rd | Q19: 4th
A20: Individual Net | B20: =IF(AND(B4=9,NOT(B6=0)),_xlfn.XLOOKUP(B6,'Side Games 9'!C14:BM14,'Side Games 9'!C16:BM16),IF(AND(B4=18,NOT(B6=0)),_xlfn.XLOOKUP(B6,'Side Games 18'!C16:BM16,'Side Games 18'!C18:BM18),"")) -> 238 | C20: =IF(AND(B4=9,NOT(B6=0)),_xlfn.XLOOKUP(B6,'Side Games 9'!C14:BM14,'Side Games 9'!C17:BM17),IF(AND(B4=18,NOT(B6=0)),_xlfn.XLOOKUP(B6,'Side Games 18'!C16:BM16,'Side Games 18'!C20:BM20),"")) -> 119 | D20: =IF(AND(B4=9,NOT(B6=0)),_xlfn.XLOOKUP(B6,'Side Games 9'!C14:BM14,'Side Games 9'!C23:BM23),IF(AND(B4=18,NOT(B6=0)),_xlfn.XLOOKUP(B6,'Side Games 18'!C16:BM16,'Side Games 18'!C36:BM36),"")) -> 1 | E20: =IF(AND(B4=9,NOT(B6=0)),_xlfn.XLOOKUP(B6,'Side Games 9'!C14:BM14,'Side Games 9'!C17:BM17),IF(AND(B4=18,NOT(B6=0)),_xlfn.XLOOKUP(B6,'Side Games 18'!C16:BM16,'Side Games 18'!C20:BM20),"")) -> 119 | F20: =IF(AND(B4=9,NOT(B6=0)),_xlfn.XLOOKUP(B6,'Side Games 9'!C14:BM14,'Side Games 9'!C18:BM18),IF(AND(B4=18,NOT(B6=0)),_xlfn.XLOOKUP(B6,'Side Games 18'!C16:BM16,'Side Games 18'!C21:BM21),"")) -> 71.4 | G20: =IF(AND(B4=9,NOT(B6=0)),_xlfn.XLOOKUP(B6,'Side Games 9'!C14:BM14,'Side Games 9'!C19:BM19),IF(AND(B4=18,NOT(B6=0)),_xlfn.XLOOKUP(B6,'Side Games 18'!C16:BM16,'Side Games 18'!C22:BM22),"")) -> 47.6 | H20: =IF(AND(B4=9,NOT(B6=0)),_xlfn.XLOOKUP(B6,'Side Games 9'!C14:BM14,'Side Games 9'!C20:BM20),IF(AND(B4=18,NOT(B6=0)),_xlfn.XLOOKUP(B6,'Side Games 18'!C16:BM16,'Side Games 18'!C23:BM23),"")) -> 0 | J20: Individual Net | K20: =IF(AND(K4=9,NOT(K6=0)),_xlfn.XLOOKUP(K5,'Side Games 9'!C14:BM14,'Side Games 9'!C16:BM16),IF(AND(K4=18,NOT(K6=0)),_xlfn.XLOOKUP(K6,'Side Games 18'!C16:BM16,'Side Games 18'!C18:BM18),"")) | L20: =IF(AND(K4=9,NOT(K6=0)),_xlfn.XLOOKUP(K6,'Side Games 9'!C14:BM14,'Side Games 9'!C17:BM17),IF(AND(K4=18,NOT(K6=0)),_xlfn.XLOOKUP(K6,'Side Games 18'!C16:BM16,'Side Games 18'!C20:BM20),"")) | M20: =IF(AND(K4=9,NOT(K6=0)),_xlfn.XLOOKUP(K6,'Side Games 9'!C14:BM14,'Side Games 9'!C23:BM23),IF(AND(K4=18,NOT(K6=0)),_xlfn.XLOOKUP(K6,'Side Games 18'!C16:BM16,'Side Games 18'!C36:BM36),"")) | N20: =IF(AND(K4=9,NOT(K6=0)),_xlfn.XLOOKUP(K6,'Side Games 9'!C14:BM14,'Side Games 9'!C17:BM17),IF(AND(K4=18,NOT(K6=0)),_xlfn.XLOOKUP(K6,'Side Games 18'!C16:BM16,'Side Games 18'!C20:BM20),"")) | O20: =IF(AND(K4=9,NOT(K6=0)),_xlfn.XLOOKUP(K6,'Side Games 9'!C14:BM14,'Side Games 9'!C18:BM18),IF(AND(K4=18,NOT(K6=0)),_xlfn.XLOOKUP(K6,'Side Games 18'!C16:BM16,'Side Games 18'!C21:BM21),"")) | P20: =IF(AND(K4=9,NOT(K6=0)),_xlfn.XLOOKUP(K6,'Side Games 9'!C14:BM14,'Side Games 9'!C19:BM19),IF(AND(K4=18,NOT(K6=0)),_xlfn.XLOOKUP(K6,'Side Games 18'!C16:BM16,'Side Games 18'!C22:BM22),"")) | Q20: =IF(AND(K4=9,NOT(K6=0)),_xlfn.XLOOKUP(K6,'Side Games 9'!C14:BM14,'Side Games 9'!C20:BM20),IF(AND(K4=18,NOT(K6=0)),_xlfn.XLOOKUP(K6,'Side Games 18'!C16:BM16,'Side Games 18'!C23:BM23),""))
A21: City MVP | B21: =IF(AND(B4=9,NOT(B6=0)),_xlfn.XLOOKUP(B6,'Side Games 9'!C14:BM14,'Side Games 9'!C24:BM24),IF(AND(B4=18,NOT(B6=0)),_xlfn.XLOOKUP(B6,'Side Games 18'!C16:BM16,'Side Games 18'!C37:BM37),"")) -> 100 | C21: =B21 -> 100 | J21: City MVP | K21: =IF(AND(K4=9,NOT(K6=0)),_xlfn.XLOOKUP(K6,'Side Games 9'!C14:BM14,'Side Games 9'!C24:BM24),IF(AND(K4=18,NOT(K6=0)),_xlfn.XLOOKUP(K6,'Side Games 18'!C16:BM16,'Side Games 18'!C37:BM37),"")) | L21: =K21
A22: TGF MVP | B22: =IF(OR(K5="",K5=0,B4=18),"No Game",SUM(B21+K21)) -> No Game | C22: =B22 -> No Game | J22: TGF MVP | K22: =IF(OR(K5="",K5=0,K4=18),"No Game",SUM(B21+K21)) -> No Game | L22: =K22 -> No Game
A23: Subtotal | B23: =SUM(B20:B22) -> 338 | C23: =SUM(C20:C22) -> 219 | J23: Subtotal | K23: =SUM(K20:K22) -> 0 | L23: =SUM(L20:L22) -> 0
A25: GROSS Games | B25: Prize Fund | C25: MWP | D25: Flights | E25: 1st | F25: 2nd | J25: GROSS Games | K25: Prize Fund | L25: MWP | M25: Flights | N25: 1st | O25: 2nd
A26: Skins | B26: =IF(AND(B4=9,NOT(B7=0)),_xlfn.XLOOKUP(B7,'Side Games 9'!C27:BM27,'Side Games 9'!C29:BM29),IF(AND(B4=18,NOT(B7=0)),_xlfn.XLOOKUP(B7,'Side Games 18'!C39:BM39,'Side Games 18'!C41:BM41),"")) -> 234 | C26: =SUM(B26/D26) -> 117 | D26: =IF(AND(B4=9,NOT(B7=0)),_xlfn.XLOOKUP(B7,'Side Games 9'!C27:BM27,'Side Games 9'!C39:BM39),IF(AND(B4=18,NOT(B7=0)),_xlfn.XLOOKUP(B7,'Side Games 18'!C39:BM39,'Side Games 18'!C51:BM51),"")) -> 2 | J26: Skins | K26: =IF(AND(K4=9,NOT(K7=0)),_xlfn.XLOOKUP(K7,'Side Games 9'!C27:BM27,'Side Games 9'!C29:BM29),IF(AND(K4=18,NOT(K7=0)),_xlfn.XLOOKUP(K7,'Side Games 18'!C39:BM39,'Side Games 18'!C41:BM41),"")) | L26: =IF(OR(K26="",K26=0),"",SUM(K26/M26)) | M26: =IF(AND(K4=9,NOT(K7=0)),_xlfn.XLOOKUP(K7,'Side Games 9'!C27:BM27,'Side Games 9'!C39:BM39),IF(AND(K4=18,NOT(K7=0)),_xlfn.XLOOKUP(K7,'Side Games 18'!C39:BM39,'Side Games 18'!C51:BM51),""))
A27: Individual Gross | B27: =IF(AND(B4=9,NOT(B7=0)),_xlfn.XLOOKUP(B7,'Side Games 9'!C27:BM27,'Side Games 9'!C40:BM40),IF(AND(B4=18,NOT(B7=0)),_xlfn.XLOOKUP(B7,'Side Games 18'!C39:BM39,'Side Games 18'!C52:BM52),"")) -> 0 | C27: =IF(AND(B4=9,NOT(B7=0)),_xlfn.XLOOKUP(B7,'Side Games 9'!C27:BM27,'Side Games 9'!C41:BM41),IF(AND(B4=18,NOT(B7=0)),_xlfn.XLOOKUP(B7,'Side Games 18'!C39:BM39,'Side Games 18'!C53:BM53),"")) -> No Game | D27: =IF(AND(B4=9,NOT(B7=0)),_xlfn.XLOOKUP(B7,'Side Games 9'!C27:BM27,'Side Games 9'!C42:BM42),IF(AND(B4=18,NOT(B7=0)),_xlfn.XLOOKUP(B7,'Side Games 18'!C39:BM39,'Side Games 18'!C55:BM55),"")) -> No Game | E27: =IF(AND(B4=9,NOT(B7=0)),_xlfn.XLOOKUP(B7,'Side Games 9'!C27:BM27,'Side Games 9'!C41:BM41),IF(AND(B4=18,NOT(B7=0)),_xlfn.XLOOKUP(B7,'Side Games 18'!C39:BM39,'Side Games 18'!C53:BM53),"")) -> No Game | F27: =IF(B4=9,0,IF(AND(B4=18,NOT(B7=0)),_xlfn.XLOOKUP(B7,'Side Games 18'!C39:BM39,'Side Games 18'!C54:BM54),"")) -> No Game | J27: Individual Gross | K27: =IF(AND(K4=9,NOT(K7=0)),_xlfn.XLOOKUP(K7,'Side Games 9'!C27:BM27,'Side Games 9'!C40:BM40),IF(AND(K4=18,NOT(K7=0)),_xlfn.XLOOKUP(K7,'Side Games 18'!C39:BM39,'Side Games 18'!C52:BM52),"")) | L27: =IF(AND(K4=9,NOT(K7=0)),_xlfn.XLOOKUP(K7,'Side Games 9'!C27:BM27,'Side Games 9'!C41:BM41),IF(AND(K4=18,NOT(K7=0)),_xlfn.XLOOKUP(K7,'Side Games 18'!C39:BM39,'Side Games 18'!C53:BM53),"")) | M27: =IF(AND(K4=9,NOT(K7=0)),_xlfn.XLOOKUP(K7,'Side Games 9'!C27:BM27,'Side Games 9'!C42:BM42),IF(AND(K4=18,NOT(K7=0)),_xlfn.XLOOKUP(K7,'Side Games 18'!C39:BM39,'Side Games 18'!C55:BM55),"")) | N27: =IF(AND(K4=9,NOT(K7=0)),_xlfn.XLOOKUP(K7,'Side Games 9'!C27:BM27,'Side Games 9'!C41:BM41),IF(AND(K4=18,NOT(K7=0)),_xlfn.XLOOKUP(K7,'Side Games 18'!C39:BM39,'Side Games 18'!C53:BM53),"")) | O27: =IF(K4=9,0,IF(AND(K4=18,NOT(K7=0)),_xlfn.XLOOKUP(K7,'Side Games 18'!C39:BM39,'Side Games 18'!C54:BM54),""))
A28: Subtotal | B28: =SUM(B26:B27) -> 234 | C28: =SUM(C26:C27) -> 117 | J28: Subtotal | K28: =SUM(K26:K27) -> 0 | L28: =SUM(L26:L27) -> 0
A30: TOTAL | B30: =SUM(B17,B23,B28) -> 824 | C30: =SUM(C17,C23,C28) -> 444 | J30: TOTAL | K30: =SUM(K17,K23,K28) -> #N/A | L30: =SUM(L17,L23,L28) -> #N/A
A31: Difference | B31: =SUM(C8-B30) -> 0 | J31: Difference | K31: =SUM(L8-K30) -> #N/A
A34: GRAND TOTAL | B34: =SUM(B30+K30) -> #N/A

Sheet Side Games 9
A1: 9 HOLE EVENTS
A2: EVENT Games | B2: 7 | C2: 2 | D2: 3 | E2: 4 | F2: 5 | G2: 6 | H2: 7 | I2: 8 | J2: 9 | K2: 10 | L2: 11 | M2: 12 | N2: 13 | O2: 14 | P2: 15 | Q2: 16 | R2: 17 | S2: 18 | T2: 19 | U2: 20 | V2: 21 | W2: 22 | X2: 23 | Y2: 24 | Z2: 25 | AA2: 26 | AB2: 27 | AC2: 28 | AD2: 29 | AE2: 30 | AF2: 31 | AG2: 32 | AH2: 33 | AI2: 34 | AJ2: 35 | AK2: 36 | AL2: 37 | AM2: 38 | AN2: 39 | AO2: 40 | AP2: 41 | AQ2: 42 | AR2: 43 | AS2: 44 | AT2: 45 | AU2: 46 | AV2: 47 | AW2: 48 | AX2: 49 | AY2: 50 | AZ2: 51 | BA2: 52 | BB2: 53 | BC2: 54 | BD2: 55 | BE2: 56 | BF2: 57 | BG2: 58 | BH2: 59 | BI2: 60 | BJ2: 61 | BK2: 62 | BL2: 63 | BM2: 64
A3: TOTAL POT | C3: =SUM(C2*$B2) -> 14 | D3: =SUM(D2*$B2) -> 21 | E3: =SUM(E2*$B2) -> 28 | F3: =SUM(F2*$B2) -> 35 | G3: =SUM(G2*$B2) -> 42 | H3: =SUM(H2*$B2) -> 49 | I3: =SUM(I2*$B2) -> 56 | J3: =SUM(J2*$B2) -> 63 | ... BM3: =SUM(BM2*$B2) -> 448
A4: TEAM GAMES | B4: 4 | C4: No Event | D4: No Event | E4: =SUM(E14*$B4)+SUM(E2*$B9) -> 24 | F4: =SUM(F14*$B4)+SUM(F2*$B9) -> 30 | G4: =SUM(G14*$B4)+SUM(G2*$B9) -> 36 | H4: =SUM(H14*$B4)+SUM(H2*$B9) -> 42 | I4: =SUM(I14*$B4)+SUM(I2*$B9) -> 48 | J4: =SUM(J14*$B4)+SUM(J2*$B9) -> 54 | K4: =SUM(K14*$B4)+SUM(K2*$B9) -> 60 | L4: =SUM(L14*$B4)+SUM(L2*$B9) -> 66 | ... P4: =SUM(P14*$B4)+SUM(P2*$B9) -> 90 | Q4: =SUM(Q14*$B4) -> 64 | R4: =SUM(R14*$B4) -> 68 | S4: =SUM(S14*$B4) -> 72 | T4: =SUM(T14*$B4) -> 76 | U4: =SUM(U14*$B4) -> 80 | V4: =SUM(V14*$B4) -> 84 | W4: =SUM(W14*$B4) -> 88 | X4: =SUM(X14*$B4) -> 92 | ... BM4: =SUM(BM14*$B4) -> 256
B5: 1st Place | C5: No Event | D5: No Event | E5: =E4 -> 24 | F5: =F4 -> 30 | G5: =G4 -> 36 | H5: =H4 -> 42 | I5: =I4 -> 48 | J5: =J4 -> 54 | K5: =K4 -> 60 | L5: =L4 -> 66 | M5: =SUM(M4*0.6666666666) -> 48 | N5: =SUM(N4*0.6666666666) -> 52 | O5: =SUM(O4*0.6666666666) -> 56 | P5: =SUM(P4*0.6666666666) -> 60 | Q5: =Q4 -> 64 | R5: =R4 -> 68 | S5: =S4 -> 72 | T5: =T4 -> 76 | U5: =U4 -> 80 | V5: =V4 -> 84 | W5: =W4 -> 88 | X5: =X4 -> 92 | ... AV5: =AV4 -> 188 | AW5: =SUM(AW4*0.6666666666) -> 128 | AX5: =SUM(AX4*0.6666666666) -> 130.66667 | AY5: =SUM(AY4*0.6666666666) -> 133.33333 | AZ5: =SUM(AZ4*0.6666666666) -> 136 | BA5: =SUM(BA4*0.6666666666) -> 138.66667 | BB5: =SUM(BB4*0.6666666666) -> 141.33333 | BC5: =SUM(BC4*0.6666666666) -> 144 | BD5: =SUM(BD4*0.6666666666) -> 146.66667 | ... BM5: =SUM(BM4*0.6666666666) -> 170.66667
B6: 2nd Place | C6: No Event | D6: No Event | M6: =SUM(M4*0.33333333333) -> 24 | N6: =SUM(N4*0.33333333333) -> 26 | O6: =SUM(O4*0.33333333333) -> 28 | P6: =SUM(P4*0.33333333333) -> 30 | AW6: =SUM(AW4*0.33333333333) -> 64 | AX6: =SUM(AX4*0.33333333333) -> 65.333333 | AY6: =SUM(AY4*0.33333333333) -> 66.666667 | AZ6: =SUM(AZ4*0.33333333333) -> 68 | BA6: =SUM(BA4*0.33333333333) -> 69.333333 | BB6: =SUM(BB4*0.33333333333) -> 70.666667 | BC6: =SUM(BC4*0.33333333333) -> 72 | BD6: =SUM(BD4*0.33333333333) -> 73.333333 | ... BM6: =SUM(BM4*0.33333333333) -> 85.333333
B7: MWP | C7: No Event | D7: No Event | E7: =IF(E8="CART Net",SUM(E5/2),IF(E8="TEAM Net",SUM(E5/4),"")) -> 12 | F7: =IF(F8="CART Net",SUM(F5/2),IF(F8="TEAM Net",SUM(F5/4),"")) -> 15 | G7: =IF(G8="CART Net",SUM(G5/2),IF(G8="TEAM Net",SUM(G5/4),"")) -> 18 | H7: =IF(H8="CART Net",SUM(H5/2),IF(H8="TEAM Net",SUM(H5/4),"")) -> 21 | I7: =IF(I8="CART Net",SUM(I5/2),IF(I8="TEAM Net",SUM(I5/4),"")) -> 24 | J7: =IF(J8="CART Net",SUM(J5/2),IF(J8="TEAM Net",SUM(J5/4),"")) -> 27 | K7: =IF(K8="CART Net",SUM(K5/2),IF(K8="TEAM Net",SUM(K5/4),"")) -> 30 | L7: =IF(L8="CART Net",SUM(L5/2),IF(L8="TEAM Net",SUM(L5/4),"")) -> 33 | ... BM7: =IF(BM8="CART Net",SUM(BM5/2),IF(BM8="TEAM Net",SUM(BM5/4),"")) -> 42.666667
C8: No Event | D8: No Event | E8: CART Net | F8: CART Net | G8: CART Net | H8: CART Net | I8: CART Net | J8: CART Net | K8: CART Net | L8: CART Net | M8: CART Net | N8: CART Net | O8: CART Net | P8: CART Net | Q8: TEAM Net | R8: TEAM Net | S8: TEAM Net | T8: TEAM Net | U8: TEAM Net | V8: TEAM Net | W8: TEAM Net | X8: TEAM Net | Y8: TEAM Net | Z8: TEAM Net | AA8: TEAM Net | AB8: TEAM Net | AC8: TEAM Net | AD8: TEAM Net | AE8: TEAM Net | AF8: TEAM Net | AG8: TEAM Net | AH8: TEAM Net | AI8: TEAM Net | AJ8: TEAM Net | AK8: TEAM Net | AL8: TEAM Net | AM8: TEAM Net | AN8: TEAM Net | AO8: TEAM Net | AP8: TEAM Net | AQ8: TEAM Net | AR8: TEAM Net | AS8: TEAM Net | AT8: TEAM Net | AU8: TEAM Net | AV8: TEAM Net | AW8: TEAM Net | AX8: TEAM Net | AY8: TEAM Net | AZ8: TEAM Net | BA8: TEAM Net | BB8: TEAM Net | BC8: TEAM Net | BD8: TEAM Net | BE8: TEAM Net | BF8: TEAM Net | BG8: TEAM Net | BH8: TEAM Net | BI8: TEAM Net | BJ8: TEAM Net | BK8: TEAM Net | BL8: TEAM Net | BM8: TEAM Net
A9: CLOSEST TO PINS | B9: 2 | C9: No Event | D9: No Event | Q9: =$B9*Q27 -> 32 | R9: =$B9*R27 -> 34 | S9: =$B9*S27 -> 36 | T9: =$B9*T27 -> 38 | U9: =SUM(U14*$B9) -> 40 | V9: =SUM(V14*$B9) -> 42 | W9: =SUM(W14*$B9) -> 44 | X9: =SUM(X14*$B9) -> 46 | Y9: =SUM(Y14*$B9) -> 48 | Z9: =SUM(Z14*$B9) -> 50 | AA9: =SUM(AA14*$B9) -> 52 | AB9: =SUM(AB14*$B9) -> 54 | ... BM9: =SUM(BM14*$B9) -> 128
A10: CLOSEST TO PIN #1 | C10: No Event | D10: No Event | E10: No Game | F10: No Game | G10: No Game | H10: No Game | I10: No Game | J10: No Game | K10: No Game | L10: No Game | M10: No Game | N10: No Game | O10: No Game | P10: No Game | Q10: =Q9*0.5 -> 16 | R10: =R9*0.5 -> 17 | S10: =S9*0.5 -> 18 | T10: =T9*0.5 -> 19 | U10: =U9*0.5 -> 20 | V10: =V9*0.5 -> 21 | W10: =W9*0.5 -> 22 | X10: =X9*0.5 -> 23 | ... BM10: =BM9*0.5 -> 64
A11: CLOSEST TO PIN #2 | C11: No Event | D11: No Event | E11: No Game | F11: No Game | G11: No Game | H11: No Game | I11: No Game | J11: No Game | K11: No Game | L11: No Game | M11: No Game | N11: No Game | O11: No Game | P11: No Game | Q11: =Q10 -> 16 | R11: =R10 -> 17 | S11: =S10 -> 18 | T11: =T10 -> 19 | U11: =U10 -> 20 | V11: =V10 -> 21 | W11: =W10 -> 22 | X11: =X10 -> 23 | ... BM11: =BM10 -> 64
A12: HOLE-IN-ONE POT | B12: 1 | C12: No Event | D12: No Event | E12: =SUM(E14*$B12) -> 4 | F12: =SUM(F14*$B12) -> 5 | G12: =SUM(G14*$B12) -> 6 | H12: =SUM(H14*$B12) -> 7 | I12: =SUM(I14*$B12) -> 8 | J12: =SUM(J14*$B12) -> 9 | K12: =SUM(K14*$B12) -> 10 | L12: =SUM(L14*$B12) -> 11 | ... BM12: =SUM(BM14*$B12) -> 64
A14: NET Games | B14: 13 | C14: 2 | D14: 3 | E14: 4 | F14: 5 | G14: 6 | H14: 7 | I14: 8 | J14: 9 | K14: 10 | L14: 11 | M14: 12 | N14: 13 | O14: 14 | P14: 15 | Q14: 16 | R14: 17 | S14: 18 | T14: 19 | U14: 20 | V14: 21 | W14: 22 | X14: 23 | Y14: 24 | Z14: 25 | AA14: 26 | AB14: 27 | AC14: 28 | AD14: 29 | AE14: 30 | AF14: 31 | AG14: 32 | AH14: 33 | AI14: 34 | AJ14: 35 | AK14: 36 | AL14: 37 | AM14: 38 | AN14: 39 | AO14: 40 | AP14: 41 | AQ14: 42 | AR14: 43 | AS14: 44 | AT14: 45 | AU14: 46 | AV14: 47 | AW14: 48 | AX14: 49 | AY14: 50 | AZ14: 51 | BA14: 52 | BB14: 53 | BC14: 54 | BD14: 55 | BE14: 56 | BF14: 57 | BG14: 58 | BH14: 59 | BI14: 60 | BJ14: 61 | BK14: 62 | BL14: 63 | BM14: 64
A15: TOTAL POT | C15: =SUM(C14*$B14) -> 26 | D15: =SUM(D14*$B14) -> 39 | E15: =SUM(E14*$B14) -> 52 | F15: =SUM(F14*$B14) -> 65 | G15: =SUM(G14*$B14) -> 78 | H15: =SUM(H14*$B14) -> 91 | I15: =SUM(I14*$B14) -> 104 | J15: =SUM(J14*$B14) -> 117 | ... BM15: =SUM(BM14*$B14) -> 832
A16: INDIVIDUAL NET | B16: 9 | C16: =SUM($B16*C14) -> 18 | D16: =SUM($B16*D14) -> 27 | E16: =SUM($B16*E14) -> 36 | F16: =SUM($B16*F14) -> 45 | G16: =SUM($B16*G14) -> 54 | H16: =SUM($B16*H14) -> 63 | I16: =SUM($B16*I14) -> 72 | J16: =SUM($B16*J14) -> 81 | ... BM16: =SUM($B16*BM14) -> 576
A17: LOW FLIGHT | B17: 1st Place | C17: No Event | D17: No Event | E17: =SUM(E16*1) -> 36 | F17: =SUM(F16*1) -> 45 | G17: =SUM(G16*1) -> 54 | H17: =SUM(H16*1) -> 63 | I17: =ROUND(SUM(I16*0.6666666),2) -> 48 | J17: =ROUND(SUM(J16*0.6666666),2) -> 54 | K17: =ROUND(SUM(K16*0.6666666),2) -> 60 | L17: =ROUND(SUM(L16*0.6666666),2) -> 66 | M17: =M16*0.5 -> 54 | N17: =N16*0.5 -> 58.5 | O17: =O16*0.5 -> 63 | P17: =P16*0.5 -> 67.5 | Q17: =ROUND(SUM(Q16*0.5*0.66666666),2) -> 48 | R17: =ROUND(SUM(R16*0.5*0.66666666),2) -> 51 | S17: =ROUND(SUM(S16*0.5*0.66666666),2) -> 54 | T17: =ROUND(SUM(T16*0.5*0.66666666),2) -> 57 | U17: =ROUND(SUM(U16*0.5*0.66666666),2) -> 60 | V17: =ROUND(SUM(V16*0.5*0.66666666),2) -> 63 | W17: =ROUND(SUM(W16*0.5*0.66666666),2) -> 66 | X17: =ROUND(SUM(X16*0.5*0.66666666),2) -> 69 | Y17: =ROUND((SUM(Y16/2)*0.6666666666666),2) -> 72 | Z17: =ROUND((SUM(Z16/2)*0.6666666666666),2) -> 75 | AA17: =ROUND((SUM(AA16/2)*0.6666666666666),2) -> 78 | AB17: =ROUND((SUM(AB16/2)*0.6666666666666),2) -> 81 | AC17: =SUM(AC16/2)*0.5 -> 63 | AD17: =SUM(AD16/2)*0.5 -> 65.25 | AE17: =SUM(AE16/2)*0.5 -> 67.5 | AF17: =SUM(AF16/2)*0.5 -> 69.75 | AG17: =SUM(AG16/2)*0.5 -> 72 | AH17: =SUM(AH16/2)*0.5 -> 74.25 | AI17: =SUM(AI16/2)*0.5 -> 76.5 | AJ17: =SUM(AJ16/2)*0.5 -> 78.75 | ... BM17: =SUM(BM16/2)*0.5 -> 144
B18: 2nd Place | C18: No Event | D18: No Event | I18: =ROUND(SUM(I16*0.333333),2) -> 24 | J18: =ROUND(SUM(J16*0.333333),2) -> 27 | K18: =ROUND(SUM(K16*0.333333),2) -> 30 | L18: =ROUND(SUM(L16*0.333333),2) -> 33 | Q18: =ROUND(SUM(Q16*0.5*0.33333333),2) -> 24 | R18: =ROUND(SUM(R16*0.5*0.33333333),2) -> 25.5 | S18: =ROUND(SUM(S16*0.5*0.33333333),2) -> 27 | T18: =ROUND(SUM(T16*0.5*0.33333333),2) -> 28.5 | U18: =ROUND(SUM(U16*0.5*0.33333333),2) -> 30 | V18: =ROUND(SUM(V16*0.5*0.33333333),2) -> 31.5 | W18: =ROUND(SUM(W16*0.5*0.33333333),2) -> 33 | X18: =ROUND(SUM(X16*0.5*0.33333333),2) -> 34.5 | Y18: =ROUND((SUM(Y16-Y17-Y20)/2),2) -> 36 | Z18: =ROUND((SUM(Z16-Z17-Z20)/2),2) -> 37.5 | AA18: =ROUND((SUM(AA16-AA17-AA20)/2),2) -> 39 | AB18: =ROUND((SUM(AB16-AB17-AB20)/2),2) -> 40.5 | AC18: =SUM(AC$16/2)*0.3 -> 37.8 | AD18: =SUM(AD$16/2)*0.3 -> 39.15 | AE18: =SUM(AE$16/2)*0.3 -> 40.5 | AF18: =SUM(AF$16/2)*0.3 -> 41.85 | AG18: =SUM(AG$16/2)*0.3 -> 43.2 | AH18: =SUM(AH$16/2)*0.3 -> 44.55 | AI18: =SUM(AI$16/2)*0.3 -> 45.9 | AJ18: =SUM(AJ$16/2)*0.3 -> 47.25 | ... BM18: =SUM(BM$16/2)*0.3 -> 86.4
B19: 3rd Place | C19: No Event | D19: No Event | AC19: =SUM(AC$16/2)*0.2 -> 25.2 | AD19: =SUM(AD$16/2)*0.2 -> 26.1 | AE19: =SUM(AE$16/2)*0.2 -> 27 | AF19: =SUM(AF$16/2)*0.2 -> 27.9 | AG19: =SUM(AG$16/2)*0.2 -> 28.8 | AH19: =SUM(AH$16/2)*0.2 -> 29.7 | AI19: =SUM(AI$16/2)*0.2 -> 30.6 | AJ19: =SUM(AJ$16/2)*0.2 -> 31.5 | ... BM19: =SUM(BM$16/2)*0.2 -> 57.6
A20: HIGH FLIGHT | B20: 1st Place | C20: No Event | D20: No Event | M20: =M17 -> 54 | N20: =N17 -> 58.5 | O20: =O17 -> 63 | P20: =P17 -> 67.5 | Q20: =Q17 -> 48 | R20: =R17 -> 51 | S20: =S17 -> 54 | T20: =T17 -> 57 | ... BM20: =BM17 -> 144
B21: 2nd Place | C21: No Event | D21: No Event | Q21: =Q18 -> 24 | R21: =R18 -> 25.5 | S21: =S18 -> 27 | T21: =T18 -> 28.5 | U21: =U18 -> 30 | V21: =V18 -> 31.5 | W21: =W18 -> 33 | X21: =X18 -> 34.5 | ... BM21: =BM18 -> 86.4
B22: 3rd Place | C22: No Event | D22: No Event | AC22: =AC19 -> 25.2 | AD22: =AD19 -> 26.1 | AE22: =AE19 -> 27 | AF22: =AF19 -> 27.9 | AG22: =AG19 -> 28.8 | AH22: =AH19 -> 29.7 | AI22: =AI19 -> 30.6 | AJ22: =AJ19 -> 31.5 | ... BM22: =BM19 -> 57.6
A23: FLIGHTS | C23: No Event | D23: No Event | E23: 1 | F23: 1 | G23: 1 | H23: 1 | I23: 1 | J23: 1 | K23: 1 | L23: 1 | M23: 2 | N23: 2 | O23: 2 | P23: 2 | Q23: 2 | R23: 2 | S23: 2 | T23: 2 | U23: 2 | V23: 2 | W23: 2 | X23: 2 | Y23: 2 | Z23: 2 | AA23: 2 | AB23: 2 | AC23: 2 | AD23: 2 | AE23: 2 | AF23: 2 | AG23: 2 | AH23: 2 | AI23: 2 | AJ23: 2 | AK23: 2 | AL23: 2 | AM23: 2 | AN23: 2 | AO23: 2 | AP23: 2 | AQ23: 2 | AR23: 2 | AS23: 2 | AT23: 2 | AU23: 2 | AV23: 2 | AW23: 2 | AX23: 2 | AY23: 2 | AZ23: 2 | BA23: 2 | BB23: 2 | BC23: 2 | BD23: 2 | BE23: 2 | BF23: 2 | BG23: 2 | BH23: 2 | BI23: 2 | BJ23: 2 | BK23: 2 | BL23: 2 | BM23: 2
A24: CITY MVP | B24: 2 | C24: =SUM(C14*$B24) -> 4 | D24: =SUM(D14*$B24) -> 6 | E24: =SUM(E14*$B24) -> 8 | F24: =SUM(F14*$B24) -> 10 | G24: =SUM(G14*$B24) -> 12 | H24: =SUM(H14*$B24) -> 14 | I24: =SUM(I14*$B24) -> 16 | J24: =SUM(J14*$B24) -> 18 | ... BM24: =SUM(BM14*$B24) -> 128
A25: TGF MVP | B25: 2 | C25: =SUM(C14*$B25) -> 4 | D25: =SUM(D14*$B25) -> 6 | E25: =SUM(E14*$B25) -> 8 | F25: =SUM(F14*$B25) -> 10 | G25: =SUM(G14*$B25) -> 12 | H25: =SUM(H14*$B25) -> 14 | I25: =SUM(I14*$B25) -> 16 | J25: =SUM(J14*$B25) -> 18 | ... BM25: =SUM(BM14*$B25) -> 128
A27: GROSS Games | B27: 15 | C27: =C14 -> 2 | D27: =D14 -> 3 | E27: =E14 -> 4 | F27: =F14 -> 5 | G27: =G14 -> 6 | H27: =H14 -> 7 | I27: =I14 -> 8 | J27: =J14 -> 9 | ... BM27: =BM14 -> 64
A28: TOTAL POT | C28: =SUM(C27*$B27) -> 30 | D28: =SUM(D27*$B27) -> 45 | E28: =SUM(E27*$B27) -> 60 | F28: =SUM(F27*$B27) -> 75 | G28: =SUM(G27*$B27) -> 90 | H28: =SUM(H27*$B27) -> 105 | I28: =SUM(I27*$B27) -> 120 | J28: =SUM(J27*$B27) -> 135 | ... BM28: =SUM(BM27*$B27) -> 960
A29: SKINS | B29: 9 | C29: =SUM($B29*C27)+SUM(C27*$B40) -> 26 | D29: =SUM($B29*D27)+SUM(D27*$B40) -> 39 | E29: =SUM($B29*E27)+SUM(E27*$B40) -> 52 | F29: =SUM($B29*F27)+SUM(F27*$B40) -> 65 | G29: =SUM($B29*G27)+SUM(G27*$B40) -> 78 | H29: =SUM($B29*H27)+SUM(H27*$B40) -> 91 | I29: =SUM($B29*I27)+SUM(I27*$B40) -> 104 | J29: =SUM($B29*J27)+SUM(J27*$B40) -> 117 | ... T29: =SUM($B29*T27)+SUM(T27*$B40) -> 247 | U29: =SUM($B29*U27) -> 180 | V29: =SUM($B29*V27) -> 189 | W29: =SUM($B29*W27) -> 198 | X29: =SUM($B29*X27) -> 207 | Y29: =SUM($B29*Y27) -> 216 | Z29: =SUM($B29*Z27) -> 225 | AA29: =SUM($B29*AA27) -> 234 | AB29: =SUM($B29*AB27) -> 243 | ... BM29: =SUM($B29*BM27) -> 576
B30: 1 Skin | C30: =C29 -> 26 | D30: =D29 -> 39 | E30: =E29 -> 52 | F30: =F29 -> 65 | G30: =G29 -> 78 | H30: =H29 -> 91 | I30: =SUM(I29/2) -> 52 | J30: =SUM(J29/2) -> 58.5 | K30: =SUM(K29/2) -> 65 | L30: =SUM(L29/2) -> 71.5 | M30: =SUM(M29/2) -> 78 | N30: =SUM(N29/2) -> 84.5 | O30: =SUM(O29/2) -> 91 | P30: =SUM(P29/2) -> 97.5 | ... BM30: =SUM(BM29/2) -> 288
B31: 2 Skins | C31: =SUM(C29/2) -> 13 | D31: =SUM(D29/2) -> 19.5 | E31: =SUM(E29/2) -> 26 | F31: =SUM(F29/2) -> 32.5 | G31: =SUM(G29/2) -> 39 | H31: =SUM(H29/2) -> 45.5 | I31: =SUM(I$30/2) -> 26 | J31: =SUM(J$30/2) -> 29.25 | K31: =SUM(K$30/2) -> 32.5 | L31: =SUM(L$30/2) -> 35.75 | M31: =SUM(M$30/2) -> 39 | N31: =SUM(N$30/2) -> 42.25 | O31: =SUM(O$30/2) -> 45.5 | P31: =SUM(P$30/2) -> 48.75 | ... BM31: =SUM(BM$30/2) -> 144
B32: 3 Skins | C32: =SUM(C29/3) -> 8.6666667 | D32: =SUM(D29/3) -> 13 | E32: =SUM(E29/3) -> 17.333333 | F32: =SUM(F29/3) -> 21.666667 | G32: =SUM(G29/3) -> 26 | H32: =SUM(H29/3) -> 30.333333 | I32: =SUM(I$30/3) -> 17.333333 | J32: =SUM(J$30/3) -> 19.5 | K32: =SUM(K$30/3) -> 21.666667 | L32: =SUM(L$30/3) -> 23.833333 | M32: =SUM(M$30/3) -> 26 | N32: =SUM(N$30/3) -> 28.166667 | O32: =SUM(O$30/3) -> 30.333333 | P32: =SUM(P$30/3) -> 32.5 | ... R32: =SUM(R$30/3) -> 36.833333 | S32: 24.67 | T32: =SUM(T$30/3) -> 41.166667 | U32: =SUM(U$30/3) -> 30 | V32: =SUM(V$30/3) -> 31.5 | W32: =SUM(W$30/3) -> 33 | X32: =SUM(X$30/3) -> 34.5 | Y32: =SUM(Y$30/3) -> 36 | Z32: =SUM(Z$30/3) -> 37.5 | AA32: =SUM(AA$30/3) -> 39 | ... BM32: =SUM(BM$30/3) -> 96
B33: 4 Skins | C33: =SUM(C29/4) -> 6.5 | D33: =SUM(D29/4) -> 9.75 | E33: =SUM(E29/4) -> 13 | F33: =SUM(F29/4) -> 16.25 | G33: =SUM(G29/4) -> 19.5 | H33: =SUM(H29/4) -> 22.75 | I33: =SUM(I$30/4) -> 13 | J33: =SUM(J$30/4) -> 14.625 | K33: =SUM(K$30/4) -> 16.25 | L33: =SUM(L$30/4) -> 17.875 | M33: =SUM(M$30/4) -> 19.5 | N33: =SUM(N$30/4) -> 21.125 | O33: =SUM(O$30/4) -> 22.75 | P33: =SUM(P$30/4) -> 24.375 | ... BM33: =SUM(BM$30/4) -> 72
B34: 5 Skins | C34: =SUM(C29/5) -> 5.2 | D34: =SUM(D29/5) -> 7.8 | E34: =SUM(E29/5) -> 10.4 | F34: =SUM(F29/5) -> 13 | G34: =SUM(G29/5) -> 15.6 | H34: =SUM(H29/5) -> 18.2 | I34: =SUM(I$30/5) -> 10.4 | J34: =SUM(J$30/5) -> 11.7 | K34: =SUM(K$30/5) -> 13 | L34: =SUM(L$30/5) -> 14.3 | M34: =SUM(M$30/5) -> 15.6 | N34: =SUM(N$30/5) -> 16.9 | O34: =SUM(O$30/5) -> 18.2 | P34: =SUM(P$30/5) -> 19.5 | ... BM34: =SUM(BM$30/5) -> 57.6
B35: 6 Skins | C35: =SUM(C29/6) -> 4.3333333 | D35: =SUM(D29/6) -> 6.5 | E35: =SUM(E29/6) -> 8.6666667 | F35: =SUM(F29/6) -> 10.833333 | G35: =SUM(G29/6) -> 13 | H35: =SUM(H29/6) -> 15.166667 | I35: =SUM(I$30/6) -> 8.6666667 | J35: =SUM(J$30/6) -> 9.75 | K35: =SUM(K$30/6) -> 10.833333 | L35: =SUM(L$30/6) -> 11.916667 | M35: =SUM(M$30/6) -> 13 | N35: =SUM(N$30/6) -> 14.083333 | O35: =SUM(O$30/6) -> 15.166667 | P35: =SUM(P$30/6) -> 16.25 | ... BM35: =SUM(BM$30/6) -> 48
B36: 7 Skins | C36: =SUM(C29/7) -> 3.7142857 | D36: =SUM(D29/7) -> 5.5714286 | E36: =SUM(E29/7) -> 7.4285714 | F36: =SUM(F29/7) -> 9.2857143 | G36: =SUM(G29/7) -> 11.142857 | H36: =SUM(H29/7) -> 13 | I36: =SUM(I$30/7) -> 7.4285714 | J36: =SUM(J$30/7) -> 8.3571429 | K36: =SUM(K$30/7) -> 9.2857143 | L36: =SUM(L$30/7) -> 10.214286 | M36: =SUM(M$30/7) -> 11.142857 | N36: =SUM(N$30/7) -> 12.071429 | O36: =SUM(O$30/7) -> 13 | P36: =SUM(P$30/7) -> 13.928571 | ... BM36: =SUM(BM$30/7) -> 41.142857
B37: 8 Skins | C37: =SUM(C29/8) -> 3.25 | D37: =SUM(D29/8) -> 4.875 | E37: =SUM(E29/8) -> 6.5 | F37: =SUM(F29/8) -> 8.125 | G37: =SUM(G29/8) -> 9.75 | H37: =SUM(H29/8) -> 11.375 | I37: =SUM(I$30/8) -> 6.5 | J37: =SUM(J$30/8) -> 7.3125 | K37: =SUM(K$30/8) -> 8.125 | L37: =SUM(L$30/8) -> 8.9375 | M37: =SUM(M$30/8) -> 9.75 | N37: =SUM(N$30/8) -> 10.5625 | O37: =SUM(O$30/8) -> 11.375 | P37: =SUM(P$30/8) -> 12.1875 | ... BM37: =SUM(BM$30/8) -> 36
B38: 9 Skins | C38: =SUM(C29/9) -> 2.8888889 | D38: =SUM(D29/9) -> 4.3333333 | E38: =SUM(E29/9) -> 5.7777778 | F38: =SUM(F29/9) -> 7.2222222 | G38: =SUM(G29/9) -> 8.6666667 | H38: =SUM(H29/9) -> 10.111111 | I38: =SUM(I$30/9) -> 5.7777778 | J38: =SUM(J$30/9) -> 6.5 | K38: =SUM(K$30/9) -> 7.2222222 | L38: =SUM(L$30/9) -> 7.9444444 | M38: =SUM(M$30/9) -> 8.6666667 | N38: =SUM(N$30/9) -> 9.3888889 | O38: =SUM(O$30/9) -> 10.111111 | P38: =SUM(P$30/9) -> 10.833333 | ... BM38: =SUM(BM$30/9) -> 32
B39: FLIGHTS | C39: 1 | D39: 1 | E39: 1 | F39: 1 | G39: 1 | H39: 1 | I39: 2 | J39: 2 | K39: 2 | L39: 2 | M39: 2 | N39: 2 | O39: 2 | P39: 2 | Q39: 2 | R39: 2 | S39: 2 | T39: 2 | U39: 2 | V39: 2 | W39: 2 | X39: 2 | Y39: 2 | Z39: 2 | AA39: 2 | AB39: 2 | AC39: 2 | AD39: 2 | AE39: 2 | AF39: 2 | AG39: 2 | AH39: 2 | AI39: 2 | AJ39: 2 | AK39: 2 | AL39: 2 | AM39: 2 | AN39: 2 | AO39: 2 | AP39: 2 | AQ39: 2 | AR39: 2 | AS39: 2 | AT39: 2 | AU39: 2 | AV39: 2 | AW39: 2 | AX39: 2 | AY39: 2 | AZ39: 2 | BA39: 2 | BB39: 2 | BC39: 2 | BD39: 2 | BE39: 2 | BF39: 2 | BG39: 2 | BH39: 2 | BI39: 2 | BJ39: 2 | BK39: 2 | BL39: 2 | BM39: 2
A40: INDIVIDUAL GROSS | B40: 4 | U40: =SUM(U27*$B40) -> 80 | V40: =SUM(V27*$B40) -> 84 | W40: =SUM(W27*$B40) -> 88 | X40: =SUM(X27*$B40) -> 92 | Y40: =SUM(Y27*$B40) -> 96 | Z40: =SUM(Z27*$B40) -> 100 | AA40: =SUM(AA27*$B40) -> 104 | AB40: =SUM(AB27*$B40) -> 108 | ... BM40: =SUM(BM27*$B40) -> 256
A41: LOW GROSS | B41: 1st Place | U41: =SUM(U40/4) -> 20 | V41: =SUM(V40/4) -> 21 | W41: =SUM(W40/4) -> 22 | X41: =SUM(X40/4) -> 23 | Y41: =SUM(Y40/4) -> 24 | Z41: =SUM(Z40/4) -> 25 | AA41: =SUM(AA40/4) -> 26 | AB41: =SUM(AB40/4) -> 27 | ... BM41: =SUM(BM40/4) -> 64
B42: FLIGHTS | C42: No Game | D42: No Game | E42: No Game | F42: No Game | G42: No Game | H42: No Game | I42: No Game | J42: No Game | K42: No Game | L42: No Game | M42: No Game | N42: No Game | O42: No Game | P42: No Game | Q42: No Game | R42: No Game | S42: No Game | T42: No Game | U42: 4 | V42: 4 | W42: 4 | X42: 4 | Y42: 4 | Z42: 4 | AA42: 4 | AB42: 4 | AC42: 4 | AD42: 4 | AE42: 4 | AF42: 4 | AG42: 4 | AH42: 4 | AI42: 4 | AJ42: 4 | AK42: 4 | AL42: 4 | AM42: 4 | AN42: 4 | AO42: 4 | AP42: 4 | AQ42: 4 | AR42: 4 | AS42: 4 | AT42: 4 | AU42: 4 | AV42: 4 | AW42: 4 | AX42: 4 | AY42: 4 | AZ42: 4 | BA42: 4 | BB42: 4 | BC42: 4 | BD42: 4 | BE42: 4 | BF42: 4 | BG42: 4 | BH42: 4 | BI42: 4 | BJ42: 4 | BK42: 4 | BL42: 4 | BM42: 4
...

Sheet Side Games 18
A1: 18 HOLE EVENTS
A2: EVENT Games | B2: 14 | C2: 2 | D2: 3 | E2: 4 | F2: 5 | G2: 6 | H2: 7 | I2: 8 | J2: 9 | K2: 10 | L2: 11 | M2: 12 | N2: 13 | O2: 14 | P2: 15 | Q2: 16 | R2: 17 | S2: 18 | T2: 19 | U2: 20 | V2: 21 | W2: 22 | X2: 23 | Y2: 24 | Z2: 25 | AA2: 26 | AB2: 27 | AC2: 28 | AD2: 29 | AE2: 30 | AF2: 31 | AG2: 32 | AH2: 33 | AI2: 34 | AJ2: 35 | AK2: 36 | AL2: 37 | AM2: 38 | AN2: 39 | AO2: 40 | AP2: 41 | AQ2: 42 | AR2: 43 | AS2: 44 | AT2: 45 | AU2: 46 | AV2: 47 | AW2: 48 | AX2: 49 | AY2: 50 | AZ2: 51 | BA2: 52 | BB2: 53 | BC2: 54 | BD2: 55 | BE2: 56 | BF2: 57 | BG2: 58 | BH2: 59 | BI2: 60 | BJ2: 61 | BK2: 62 | BL2: 63 | BM2: 64
A3: TOTAL POT | C3: =SUM(C2*$B2) -> 28 | D3: =SUM(D2*$B2) -> 42 | E3: =SUM(E2*$B2) -> 56 | F3: =SUM(F2*$B2) -> 70 | G3: =SUM(G2*$B2) -> 84 | H3: =SUM(H2*$B2) -> 98 | I3: =SUM(I2*$B2) -> 112 | J3: =SUM(J2*$B2) -> 126 | ... BM3: =SUM(BM2*$B2) -> 896
A4: TEAM GAMES | B4: 8 | C4: No Event | D4: No Event | E4: =SUM(E2*$B4)+SUM(E2*$B9) -> 48 | F4: =SUM(F2*$B4)+SUM(F2*$B9) -> 60 | G4: =SUM(G2*$B4)+SUM(G2*$B9) -> 72 | H4: =SUM(H2*$B4)+SUM(H2*$B9) -> 84 | I4: =SUM(I2*$B4)+SUM(I2*$B9) -> 96 | J4: =SUM(J2*$B4)+SUM(J2*$B9) -> 108 | K4: =SUM(K2*$B4)+SUM(K2*$B9) -> 120 | L4: =SUM(L2*$B4)+SUM(L2*$B9) -> 132 | ... P4: =SUM(P2*$B4)+SUM(P2*$B9) -> 180 | Q4: =SUM(Q2*$B4) -> 128 | R4: =SUM(R2*$B4) -> 136 | S4: =SUM(S2*$B4) -> 144 | T4: =SUM(T2*$B4) -> 152 | U4: =SUM(U2*$B4) -> 160 | V4: =SUM(V2*$B4) -> 168 | W4: =SUM(W2*$B4) -> 176 | X4: =SUM(X2*$B4) -> 184 | ... BM4: =SUM(BM2*$B4) -> 512
B5: 1st Place | C5: No Event | D5: No Event | E5: =E4 -> 48 | F5: =F4 -> 60 | G5: =G4 -> 72 | H5: =H4 -> 84 | I5: =I4 -> 96 | J5: =J4 -> 108 | K5: =K4 -> 120 | L5: =L4 -> 132 | M5: =SUM(M4*0.6666666666) -> 96 | N5: =SUM(N4*0.6666666666) -> 104 | O5: =SUM(O4*0.6666666666) -> 112 | P5: =SUM(P4*0.6666666666) -> 120 | Q5: =Q4 -> 128 | R5: =R4 -> 136 | S5: =S4 -> 144 | T5: =T4 -> 152 | U5: =U4 -> 160 | V5: =V4 -> 168 | W5: =W4 -> 176 | X5: =X4 -> 184 | ... AJ5: =AJ4 -> 280 | AK5: =SUM(AK4*0.6666666666) -> 192 | AL5: =SUM(AL4*0.6666666666) -> 197.33333 | AM5: =SUM(AM4*0.6666666666) -> 202.66667 | AN5: =SUM(AN4*0.6666666666) -> 208 | AO5: =SUM(AO4*0.6666666666) -> 213.33333 | AP5: =SUM(AP4*0.6666666666) -> 218.66667 | AQ5: =SUM(AQ4*0.6666666666) -> 224 | AR5: =SUM(AR4*0.6666666666) -> 229.33333 | ... BM5: =SUM(BM4*0.6666666666) -> 341.33333
B6: 2nd Place | C6: No Event | D6: No Event | M6: =SUM(M4*0.33333333333) -> 48 | N6: =SUM(N4*0.33333333333) -> 52 | O6: =SUM(O4*0.33333333333) -> 56 | P6: =SUM(P4*0.33333333333) -> 60 | AK6: =SUM(AK4*0.33333333333) -> 96 | AL6: =SUM(AL4*0.33333333333) -> 98.666667 | AM6: =SUM(AM4*0.33333333333) -> 101.33333 | AN6: =SUM(AN4*0.33333333333) -> 104 | AO6: =SUM(AO4*0.33333333333) -> 106.66667 | AP6: =SUM(AP4*0.33333333333) -> 109.33333 | AQ6: =SUM(AQ4*0.33333333333) -> 112 | AR6: =SUM(AR4*0.33333333333) -> 114.66667 | ... BM6: =SUM(BM4*0.33333333333) -> 170.66667
B7: MWP | C7: No Event | D7: No Event | E7: =IF(E8="CART Net",SUM(E5/2),IF(E8="TEAM Net",SUM(E5/4),"")) -> 24 | F7: =IF(F8="CART Net",SUM(F5/2),IF(F8="TEAM Net",SUM(F5/4),"")) -> 30 | G7: =IF(G8="CART Net",SUM(G5/2),IF(G8="TEAM Net",SUM(G5/4),"")) -> 36 | H7: =IF(H8="CART Net",SUM(H5/2),IF(H8="TEAM Net",SUM(H5/4),"")) -> 42 | I7: =IF(I8="CART Net",SUM(I5/2),IF(I8="TEAM Net",SUM(I5/4),"")) -> 48 | J7: =IF(J8="CART Net",SUM(J5/2),IF(J8="TEAM Net",SUM(J5/4),"")) -> 54 | K7: =IF(K8="CART Net",SUM(K5/2),IF(K8="TEAM Net",SUM(K5/4),"")) -> 60 | L7: =IF(L8="CART Net",SUM(L5/2),IF(L8="TEAM Net",SUM(L5/4),"")) -> 66 | ... BM7: =IF(BM8="CART Net",SUM(BM5/2),IF(BM8="TEAM Net",SUM(BM5/4),"")) -> 85.333333
C8: No Event | D8: No Event | E8: CART Net | F8: CART Net | G8: CART Net | H8: CART Net | I8: CART Net | J8: CART Net | K8: CART Net | L8: CART Net | M8: CART Net | N8: CART Net | O8: CART Net | P8: CART Net | Q8: TEAM Net | R8: TEAM Net | S8: TEAM Net | T8: TEAM Net | U8: TEAM Net | V8: TEAM Net | W8: TEAM Net | X8: TEAM Net | Y8: TEAM Net | Z8: TEAM Net | AA8: TEAM Net | AB8: TEAM Net | AC8: TEAM Net | AD8: TEAM Net | AE8: TEAM Net | AF8: TEAM Net | AG8: TEAM Net | AH8: TEAM Net | AI8: TEAM Net | AJ8: TEAM Net | AK8: TEAM Net | AL8: TEAM Net | AM8: TEAM Net | AN8: TEAM Net | AO8: TEAM Net | AP8: TEAM Net | AQ8: TEAM Net | AR8: TEAM Net | AS8: TEAM Net | AT8: TEAM Net | AU8: TEAM Net | AV8: TEAM Net | AW8: TEAM Net | AX8: TEAM Net | AY8: TEAM Net | AZ8: TEAM Net | BA8: TEAM Net | BB8: TEAM Net | BC8: TEAM Net | BD8: TEAM Net | BE8: TEAM Net | BF8: TEAM Net | BG8: TEAM Net | BH8: TEAM Net | BI8: TEAM Net | BJ8: TEAM Net | BK8: TEAM Net | BL8: TEAM Net | BM8: TEAM Net
A9: CLOSEST TO PINS | B9: 4 | C9: No Event | D9: No Event | Q9: =SUM(Q2*$B9) -> 64 | R9: =SUM(R2*$B9) -> 68 | S9: =SUM(S2*$B9) -> 72 | T9: =SUM(T2*$B9) -> 76 | U9: =SUM(U2*$B9) -> 80 | V9: =SUM(V2*$B9) -> 84 | W9: =SUM(W2*$B9) -> 88 | X9: =SUM(X2*$B9) -> 92 | ... BM9: =SUM(BM2*$B9) -> 256
A10: CLOSEST TO PIN #1 | C10: No Event | D10: No Event | E10: No Game | F10: No Game | G10: No Game | H10: No Game | I10: No Game | J10: No Game | K10: No Game | L10: No Game | M10: No Game | N10: No Game | O10: No Game | P10: No Game | Q10: =Q9/2 -> 32 | R10: =R9/2 -> 34 | S10: =S9/2 -> 36 | T10: =T9/2 -> 38 | U10: =U9/2 -> 40 | V10: =V9/2 -> 42 | W10: =W9/2 -> 44 | X10: =X9/2 -> 46 | Y10: =Y9/3 -> 32 | Z10: =Z9/3 -> 33.333333 | AA10: =AA9/3 -> 34.666667 | AB10: =AB9/3 -> 36 | AC10: =AC9/3 -> 37.333333 | AD10: =AD9/3 -> 38.666667 | AE10: =AE9/3 -> 40 | AF10: =AF9/3 -> 41.333333 | AG10: =AG9/4 -> 32 | AH10: =AH9/4 -> 33 | AI10: =AI9/4 -> 34 | AJ10: =AJ9/4 -> 35 | AK10: =AK9/4 -> 36 | AL10: =AL9/4 -> 37 | AM10: =AM9/4 -> 38 | AN10: =AN9/4 -> 39 | ... BM10: =BM9/4 -> 64
A11: CLOSEST TO PIN #2 | C11: No Event | D11: No Event | E11: No Game | F11: No Game | G11: No Game | H11: No Game | I11: No Game | J11: No Game | K11: No Game | L11: No Game | M11: No Game | N11: No Game | O11: No Game | P11: No Game | Q11: =Q10 -> 32 | R11: =R10 -> 34 | S11: =S10 -> 36 | T11: =T10 -> 38 | U11: =U10 -> 40 | V11: =V10 -> 42 | W11: =W10 -> 44 | X11: =X10 -> 46 | ... BM11: =BM10 -> 64
A12: CLOSEST TO PIN #3 | C12: No Event | D12: No Event | E12: No Game | F12: No Game | G12: No Game | H12: No Game | I12: No Game | J12: No Game | K12: No Game | L12: No Game | M12: No Game | N12: No Game | O12: No Game | P12: No Game | Q12: No Game | R12: No Game | S12: No Game | T12: No Game | U12: No Game | V12: No Game | W12: No Game | X12: No Game | Y12: =Y11 -> 32 | Z12: =Z11 -> 33.333333 | AA12: =AA11 -> 34.666667 | AB12: =AB11 -> 36 | AC12: =AC11 -> 37.333333 | AD12: =AD11 -> 38.666667 | AE12: =AE11 -> 40 | AF12: =AF11 -> 41.333333 | ... BM12: =BM11 -> 64
A13: CLOSEST TO PIN #4 | C13: No Event | D13: No Event | E13: No Game | F13: No Game | G13: No Game | H13: No Game | I13: No Game | J13: No Game | K13: No Game | L13: No Game | M13: No Game | N13: No Game | O13: No Game | P13: No Game | Q13: No Game | R13: No Game | S13: No Game | T13: No Game | U13: No Game | V13: No Game | W13: No Game | X13: No Game | Y13: No Game | Z13: No Game | AA13: No Game | AB13: No Game | AC13: No Game | AD13: No Game | AE13: No Game | AF13: No Game | AG13: =AG12 -> 32 | AH13: =AH12 -> 33 | AI13: =AI12 -> 34 | AJ13: =AJ12 -> 35 | AK13: =AK12 -> 36 | AL13: =AL12 -> 37 | AM13: =AM12 -> 38 | AN13: =AN12 -> 39 | ... BM13: =BM12 -> 64
A14: HOLE-IN-ONE POT | B14: 2 | C14: No Event | D14: No Event | E14: =SUM(E2*$B14) -> 8 | F14: =SUM(F2*$B14) -> 10 | G14: =SUM(G2*$B14) -> 12 | H14: =SUM(H2*$B14) -> 14 | I14: =SUM(I2*$B14) -> 16 | J14: =SUM(J2*$B14) -> 18 | K14: =SUM(K2*$B14) -> 20 | L14: =SUM(L2*$B14) -> 22 | ... BM14: =SUM(BM2*$B14) -> 128
A16: NET Games | B16: 26 | C16: 2 | D16: 3 | E16: 4 | F16: 5 | G16: 6 | H16: 7 | I16: 8 | J16: 9 | K16: 10 | L16: 11 | M16: 12 | N16: 13 | O16: 14 | P16: 15 | Q16: 16 | R16: 17 | S16: 18 | T16: 19 | U16: 20 | V16: 21 | W16: 22 | X16: 23 | Y16: 24 | Z16: 25 | AA16: 26 | AB16: 27 | AC16: 28 | AD16: 29 | AE16: 30 | AF16: 31 | AG16: 32 | AH16: 33 | AI16: 34 | AJ16: 35 | AK16: 36 | AL16: 37 | AM16: 38 | AN16: 39 | AO16: 40 | AP16: 41 | AQ16: 42 | AR16: 43 | AS16: 44 | AT16: 45 | AU16: 46 | AV16: 47 | AW16: 48 | AX16: 49 | AY16: 50 | AZ16: 51 | BA16: 52 | BB16: 53 | BC16: 54 | BD16: 55 | BE16: 56 | BF16: 57 | BG16: 58 | BH16: 59 | BI16: 60 | BJ16: 61 | BK16: 62 | BL16: 63 | BM16: 64
A17: TOTAL POT | C17: =SUM(C16*$B16) -> 52 | D17: =SUM(D16*$B16) -> 78 | E17: =SUM(E16*$B16) -> 104 | F17: =SUM(F16*$B16) -> 130 | G17: =SUM(G16*$B16) -> 156 | H17: =SUM(H16*$B16) -> 182 | I17: =SUM(I16*$B16) -> 208 | J17: =SUM(J16*$B16) -> 234 | ... BM17: =SUM(BM16*$B16) -> 1664
A18: INDIVIDUAL NET | B18: 18 | C18: No Event | D18: No Event | E18: =SUM($B18*E16) -> 72 | F18: =SUM($B18*F16) -> 90 | G18: =SUM($B18*G16) -> 108 | H18: =SUM($B18*H16) -> 126 | I18: =SUM($B18*I16) -> 144 | J18: =SUM($B18*J16) -> 162 | K18: =SUM($B18*K16) -> 180 | L18: =SUM($B18*L16) -> 198 | M18: =SUM($B18*M16) -> 216 | N18: =SUM($B18*N16)+SUM(SUM(N16*$B37)-N37) -> 238 | O18: =SUM($B18*O16)+SUM(SUM(O16*$B37)-O37) -> 264 | P18: =SUM($B18*P16)+SUM(SUM(P16*$B37)-P37) -> 290 | Q18: =SUM($B18*Q16)+SUM(SUM(Q16*$B37)-Q37) -> 316 | R18: =SUM($B18*R16)+SUM(SUM(R16*$B37)-R37) -> 342 | S18: =SUM($B18*S16)+SUM(SUM(S16*$B37)-S37) -> 368 | T18: =SUM($B18*T16)+SUM(SUM(T16*$B37)-T37) -> 394 | U18: =SUM($B18*U16)+SUM(SUM(U16*$B37)-U37) -> 420 | ... BM18: =SUM($B18*BM16)+SUM(SUM(BM16*$B37)-BM37) -> 1564
A19: % Paid | B19: 0.25 | C19: No Event | D19: No Event | E19: =ROUND(SUM(E16*$B19),0) -> 1 | F19: =ROUND(SUM(F16*$B19),0) -> 1 | G19: =ROUND(SUM(G16*$B19),0) -> 2 | H19: =ROUND(SUM(H16*$B19),0) -> 2 | I19: =ROUND(SUM(I16*$B19),0) -> 2 | J19: =ROUND(SUM(J16*$B19),0) -> 2 | K19: =ROUND(SUM(K16*$B19),0) -> 3 | L19: =ROUND(SUM(L16*$B19),0) -> 3 | ... BM19: =ROUND(SUM(BM16*$B19),0) -> 16
A20: LOW FLIGHT | B20: 1st Place | C20: No Event | D20: No Event | E20: =SUM(E18*1) -> 72 | F20: =SUM(F18*1) -> 90 | G20: =ROUND(SUM(G18*0.6666666),2) -> 72 | H20: =ROUND(SUM(H18*0.6666666),2) -> 84 | I20: =ROUND(SUM(I18*0.6666666),2) -> 96 | J20: =ROUND(SUM(J18*0.6666666),2) -> 108 | K20: =SUM(K18*0.5) -> 90 | L20: =SUM(L18*0.5) -> 99 | M20: =SUM(M18*0.5) -> 108 | N20: =SUM(N18*0.5) -> 119 | O20: =ROUND((SUM(O18/O36)*0.6666666666666),2) -> 88 | P20: =ROUND((SUM(P18/P36)*0.6666666666666),2) -> 96.67 | Q20: =ROUND((SUM(Q18/Q36)*0.6666666666666),2) -> 105.33 | R20: =ROUND((SUM(R18/R36)*0.6666666666666),2) -> 114 | S20: =ROUND(SUM((S18/S36)*0.5),2) -> 92 | T20: =ROUND(SUM((T18/T36)*0.5),2) -> 98.5 | U20: =ROUND(SUM((U18/U36)*0.5),2) -> 105 | V20: =ROUND(SUM((V18/V36)*0.5),2) -> 111.5 | W20: =ROUND(SUM((W18/W36)*0.5),2) -> 118 | X20: =ROUND(SUM((X18/X36)*0.5),2) -> 124.5 | Y20: =ROUND(SUM((Y18/Y36)*0.5),2) -> 131 | Z20: =ROUND(SUM((Z18/Z36)*0.5),2) -> 137.5 | AA20: =ROUND(SUM((AA18/AA36)*0.5),2) -> 144 | AB20: =ROUND(SUM((AB18/AB36)*0.4),2) -> 120.4 | AC20: =ROUND(SUM((AC18/AC36)*0.4),2) -> 125.6 | AD20: =ROUND(SUM((AD18/AD36)*0.4),2) -> 130.8 | AE20: =ROUND(SUM((AE18/AE36)*0.4),2) -> 136 | AF20: =ROUND(SUM((AF18/AF36)*0.4),2) -> 141.2 | AG20: =ROUND(SUM((AG18/AG36)*0.4),2) -> 146.4 | AH20: =ROUND(SUM((AH18/AH36)*0.4),2) -> 151.6 | AI20: =ROUND(SUM((AI18/AI36)*0.5),2) -> 130.67 | AJ20: =ROUND(SUM((AJ18/AJ36)*0.5),2) -> 135 | AK20: =ROUND(SUM((AK18/AK36)*0.5),2) -> 139.33 | AL20: =ROUND(SUM((AL18/AL36)*0.5),2) -> 143.67 | AM20: =ROUND(SUM((AM18/AM36)*0.5),2) -> 148 | AN20: =ROUND(SUM((AN18/AN36)*0.4),2) -> 121.87 | AO20: =ROUND(SUM((AO18/AO36)*0.4),2) -> 125.33 | AP20: =ROUND(SUM((AP18/AP36)*0.4),2) -> 128.8 | AQ20: =ROUND(SUM((AQ18/AQ36)*0.4),2) -> 132.27 | AR20: =ROUND(SUM((AR18/AR36)*0.4),2) -> 135.73 | AS20: =ROUND(SUM((AS18/AS36)*0.4),2) -> 139.2 | AT20: =ROUND(SUM((AT18/AT36)*0.4),2) -> 142.67 | AU20: =ROUND(SUM((AU18/AU36)*0.4),2) -> 146.13 | ... BM20: =ROUND(SUM((BM18/BM36)*0.4),2) -> 156.4
B21: 2nd Place | C21: No Event | D21: No Event | G21: =ROUND(SUM(G18*0.333333),2) -> 36 | H21: =ROUND(SUM(H18*0.333333),2) -> 42 | I21: =ROUND(SUM(I18*0.333333),2) -> 48 | J21: =ROUND(SUM(J18*0.333333),2) -> 54 | K21: =SUM(K18*0.3) -> 54 | L21: =SUM(L18*0.3) -> 59.4 | M21: =SUM(M18*0.3) -> 64.8 | N21: =SUM(N18*0.3) -> 71.4 | O21: =ROUND((SUM(O18/O36)*0.333333333333333),2) -> 44 | P21: =ROUND((SUM(P18/P36)*0.333333333333333),2) -> 48.33 | Q21: =ROUND((SUM(Q18/Q36)*0.333333333333333),2) -> 52.67 | R21: =ROUND((SUM(R18/R36)*0.333333333333333),2) -> 57 | S21: =ROUND(SUM((S$18/S36)*0.3),2) -> 55.2 | T21: =ROUND(SUM((T$18/T36)*0.3),2) -> 59.1 | U21: =ROUND(SUM((U$18/U36)*0.3),2) -> 63 | V21: =ROUND(SUM((V$18/V36)*0.3),2) -> 66.9 | W21: =ROUND(SUM((W$18/W36)*0.3),2) -> 70.8 | X21: =ROUND(SUM((X$18/X36)*0.3),2) -> 74.7 | Y21: =ROUND(SUM((Y$18/Y36)*0.3),2) -> 78.6 | Z21: =ROUND(SUM((Z$18/Z36)*0.3),2) -> 82.5 | ... BM21: =ROUND(SUM((BM$18/BM36)*0.3),2) -> 117.3
B22: 3rd Place | C22: No Event | D22: No Event | K22: =SUM(K18*0.2) -> 36 | L22: =SUM(L18*0.2) -> 39.6 | M22: =SUM(M18*0.2) -> 43.2 | N22: =SUM(N18*0.2) -> 47.6 | S22: =ROUND(SUM((S$18/S36)*0.2),2) -> 36.8 | T22: =ROUND(SUM((T$18/T36)*0.2),2) -> 39.4 | U22: =ROUND(SUM((U$18/U36)*0.2),2) -> 42 | V22: =ROUND(SUM((V$18/V36)*0.2),2) -> 44.6 | W22: =ROUND(SUM((W$18/W36)*0.2),2) -> 47.2 | X22: =ROUND(SUM((X$18/X36)*0.2),2) -> 49.8 | Y22: =ROUND(SUM((Y$18/Y36)*0.2),2) -> 52.4 | Z22: =ROUND(SUM((Z$18/Z36)*0.2),2) -> 55 | ... BM22: =ROUND(SUM((BM$18/BM36)*0.2),2) -> 78.2
B23: 4th Place | C23: No Event | D23: No Event | AB23: =ROUND(SUM((AB$18/AB36)*0.1),2) -> 30.1 | AC23: =ROUND(SUM((AC$18/AC36)*0.1),2) -> 31.4 | AD23: =ROUND(SUM((AD$18/AD36)*0.1),2) -> 32.7 | AE23: =ROUND(SUM((AE$18/AE36)*0.1),2) -> 34 | AF23: =ROUND(SUM((AF$18/AF36)*0.1),2) -> 35.3 | AG23: =ROUND(SUM((AG$18/AG36)*0.1),2) -> 36.6 | AH23: =ROUND(SUM((AH$18/AH36)*0.1),2) -> 37.9 | AN23: =ROUND(SUM((AN$18/AN36)*0.1),2) -> 30.47 | AO23: =ROUND(SUM((AO$18/AO36)*0.1),2) -> 31.33 | AP23: =ROUND(SUM((AP$18/AP36)*0.1),2) -> 32.2 | AQ23: =ROUND(SUM((AQ$18/AQ36)*0.1),2) -> 33.07 | AR23: =ROUND(SUM((AR$18/AR36)*0.1),2) -> 33.93 | AS23: =ROUND(SUM((AS$18/AS36)*0.1),2) -> 34.8 | AT23: =ROUND(SUM((AT$18/AT36)*0.1),2) -> 35.67 | AU23: =ROUND(SUM((AU$18/AU36)*0.1),2) -> 36.53 | ... BM23: =ROUND(SUM((BM$18/BM36)*0.1),2) -> 39.1
A24: HIGH FLIGHT | B24: 1st Place | C24: No Event | D24: No Event | O24: =O20 -> 88 | P24: =P20 -> 96.67 | Q24: =Q20 -> 105.33 | R24: =R20 -> 114 | S24: =S20 -> 92 | T24: =T20 -> 98.5 | U24: =U20 -> 105 | V24: =V20 -> 111.5 | ... BM24: =BM20 -> 156.4
B25: 2nd Place | C25: No Event | D25: No Event | O25: =O21 -> 44 | P25: =P21 -> 48.33 | Q25: =Q21 -> 52.67 | R25: =R21 -> 57 | S25: =S21 -> 55.2 | T25: =T21 -> 59.1 | U25: =U21 -> 63 | V25: =V21 -> 66.9 | ... BM25: =BM21 -> 117.3
B26: 3rd Place | C26: No Event | D26: No Event | S26: =S22 -> 36.8 | T26: =T22 -> 39.4 | U26: =U22 -> 42 | V26: =V22 -> 44.6 | W26: =W22 -> 47.2 | X26: =X22 -> 49.8 | Y26: =Y22 -> 52.4 | Z26: =Z22 -> 55 | ... BM26: =BM22 -> 78.2
B27: 4th Place | C27: No Event | D27: No Event | AB27: =AB23 -> 30.1 | AC27: =AC23 -> 31.4 | AD27: =AD23 -> 32.7 | AE27: =AE23 -> 34 | AF27: =AF23 -> 35.3 | AG27: =AG23 -> 36.6 | AH27: =AH23 -> 37.9 | AN27: =AN23 -> 30.47 | AO27: =AO23 -> 31.33 | AP27: =AP23 -> 32.2 | AQ27: =AQ23 -> 33.07 | AR27: =AR23 -> 33.93 | AS27: =AS23 -> 34.8 | AT27: =AT23 -> 35.67 | AU27: =AU23 -> 36.53 | ... BM27: =BM23 -> 39.1
A28: MID FLIGHT | B28: 1st Place | C28: No Event | D28: No Event | AI28: =AI20 -> 130.67 | AJ28: =AJ20 -> 135 | AK28: =AK20 -> 139.33 | AL28: =AL20 -> 143.67 | AM28: =AM20 -> 148 | AN28: =AN20 -> 121.87 | AO28: =AO20 -> 125.33 | AP28: =AP20 -> 128.8 | ... BM28: =BM20 -> 156.4
B29: 2nd Place | C29: No Event | D29: No Event | AI29: =AI21 -> 78.4 | AJ29: =AJ21 -> 81 | AK29: =AK21 -> 83.6 | AL29: =AL21 -> 86.2 | AM29: =AM21 -> 88.8 | AN29: =AN21 -> 91.4 | AO29: =AO21 -> 94 | AP29: =AP21 -> 96.6 | ... BM29: =BM21 -> 117.3
B30: 3rd Place | C30: No Event | D30: No Event | AI30: =AI22 -> 52.27 | AJ30: =AJ22 -> 54 | AK30: =AK22 -> 55.73 | AL30: =AL22 -> 57.47 | AM30: =AM22 -> 59.2 | AN30: =AN22 -> 60.93 | AO30: =AO22 -> 62.67 | AP30: =AP22 -> 64.4 | ... BM30: =BM22 -> 78.2
B31: 4th Place | C31: No Event | D31: No Event | AN31: =AN27 -> 30.47 | AO31: =AO27 -> 31.33 | AP31: =AP27 -> 32.2 | AQ31: =AQ27 -> 33.07 | AR31: =AR27 -> 33.93 | AS31: =AS27 -> 34.8 | AT31: =AT27 -> 35.67 | AU31: =AU27 -> 36.53 | ... BM31: =BM27 -> 39.1
A32: 4TH FLIGHT | B32: 1st Place | C32: No Event | D32: No Event | AY32: =AY20 -> 120 | AZ32: =AZ20 -> 122.6 | BA32: =BA20 -> 125.2 | BB32: =BB20 -> 127.8 | BC32: =BC20 -> 130.4 | BD32: =BD20 -> 133 | BE32: =BE20 -> 135.6 | BF32: =BF20 -> 138.2 | ... BM32: =BM20 -> 156.4
B33: 2nd Place | C33: No Event | D33: No Event | AY33: =AY21 -> 90 | AZ33: =AZ21 -> 91.95 | BA33: =BA21 -> 93.9 | BB33: =BB21 -> 95.85 | BC33: =BC21 -> 97.8 | BD33: =BD21 -> 99.75 | BE33: =BE21 -> 101.7 | BF33: =BF21 -> 103.65 | ... BM33: =BM21 -> 117.3
B34: 3rd Place | C34: No Event | D34: No Event | AY34: =AY22 -> 60 | AZ34: =AZ22 -> 61.3 | BA34: =BA22 -> 62.6 | BB34: =BB22 -> 63.9 | BC34: =BC22 -> 65.2 | BD34: =BD22 -> 66.5 | BE34: =BE22 -> 67.8 | BF34: =BF22 -> 69.1 | ... BM34: =BM22 -> 78.2
B35: 4th Place | C35: No Event | D35: No Event | AY35: =AY23 -> 30 | AZ35: =AZ23 -> 30.65 | BA35: =BA23 -> 31.3 | BB35: =BB23 -> 31.95 | BC35: =BC23 -> 32.6 | BD35: =BD23 -> 33.25 | BE35: =BE23 -> 33.9 | BF35: =BF23 -> 34.55 | ... BM35: =BM23 -> 39.1
A36: FLIGHTS | C36: No Event | D36: No Event | E36: 1 | F36: 1 | G36: 1 | H36: 1 | I36: 1 | J36: 1 | K36: 1 | L36: 1 | M36: 1 | N36: 1 | O36: 2 | P36: 2 | Q36: 2 | R36: 2 | S36: 2 | T36: 2 | U36: 2 | V36: 2 | W36: 2 | X36: 2 | Y36: 2 | Z36: 2 | AA36: 2 | AB36: 2 | AC36: 2 | AD36: 2 | AE36: 2 | AF36: 2 | AG36: 2 | AH36: 2 | AI36: 3 | AJ36: 3 | AK36: 3 | AL36: 3 | AM36: 3 | AN36: 3 | AO36: 3 | AP36: 3 | AQ36: 3 | AR36: 3 | AS36: 3 | AT36: 3 | AU36: 3 | AV36: 3 | AW36: 3 | AX36: 3 | AY36: 4 | AZ36: 4 | BA36: 4 | BB36: 4 | BC36: 4 | BD36: 4 | BE36: 4 | BF36: 4 | BG36: 4 | BH36: 4 | BI36: 4 | BJ36: 4 | BK36: 4 | BL36: 4 | BM36: 4
A37: MVP | B37: 8 | C37: =SUM(C16*$B37) -> 16 | D37: =SUM(D16*$B37) -> 24 | E37: =SUM(E16*$B37) -> 32 | F37: =SUM(F16*$B37) -> 40 | G37: =SUM(G16*$B37) -> 48 | H37: =SUM(H16*$B37) -> 56 | I37: =SUM(I16*$B37) -> 64 | J37: =SUM(J16*$B37) -> 72 | ... M37: =SUM(M16*$B37) -> 96 | N37: 100 | O37: 100 | P37: 100 | Q37: 100 | R37: 100 | S37: 100 | T37: 100 | U37: 100 | V37: 100 | W37: 100 | X37: 100 | Y37: 100 | Z37: 100 | AA37: 100 | AB37: 100 | AC37: 100 | AD37: 100 | AE37: 100 | AF37: 100 | AG37: 100 | AH37: 100 | AI37: 100 | AJ37: 100 | AK37: 100 | AL37: 100 | AM37: 100 | AN37: 100 | AO37: 100 | AP37: 100 | AQ37: 100 | AR37: 100 | AS37: 100 | AT37: 100 | AU37: 100 | AV37: 100 | AW37: 100 | AX37: 100 | AY37: 100 | AZ37: 100 | BA37: 100 | BB37: 100 | BC37: 100 | BD37: 100 | BE37: 100 | BF37: 100 | BG37: 100 | BH37: 100 | BI37: 100 | BJ37: 100 | BK37: 100 | BL37: 100 | BM37: 100
E38: 1/2 NET SKINS | I38: GROSS SKINS
A39: GROSS Games | B39: 26 | C39: =C2 -> 2 | D39: =D2 -> 3 | E39: =E2 -> 4 | F39: =F2 -> 5 | G39: =G2 -> 6 | H39: =H2 -> 7 | I39: =I2 -> 8 | J39: =J2 -> 9 | ... BM39: =BM2 -> 64
A40: TOTAL POT | C40: =SUM(C39*$B39) -> 52 | D40: =SUM(D39*$B39) -> 78 | E40: =SUM(E39*$B39) -> 104 | F40: =SUM(F39*$B39) -> 130 | G40: =SUM(G39*$B39) -> 156 | H40: =SUM(H39*$B39) -> 182 | I40: =SUM(I39*$B39) -> 208 | J40: =SUM(J39*$B39) -> 234 | ... BM40: =SUM(BM39*$B39) -> 1664
A41: SKINS | B41: 18 | C41: No Event | D41: No Event | E41: =E40 -> 104 | F41: =F40 -> 130 | G41: =G40 -> 156 | H41: =H40 -> 182 | I41: =I40 -> 208 | J41: =J40 -> 234 | K41: =K40 -> 260 | L41: =L40 -> 286 | ... P41: =P40 -> 390 | Q41: =SUM($B41*Q39) -> 288 | R41: =SUM($B41*R39) -> 306 | S41: =SUM($B41*S39) -> 324 | T41: =SUM($B41*T39) -> 342 | U41: =SUM($B41*U39) -> 360 | V41: =SUM($B41*V39) -> 378 | W41: =SUM($B41*W39) -> 396 | X41: =SUM($B41*X39) -> 414 | ... BM41: =SUM($B41*BM39) -> 1152
...

Sheet Calendar
B1: M | C1: T | D1: W | E1: R | F1: F | G1: Sa | H1: Su | I1: EVENTS
A2: JAN | B2: 46020 | C2: =B2+1 -> 46021 | D2: =C2+1 -> 46022 | E2: =D2+1 -> 46023 | F2: =E2+1 -> 46024 | G2: =F2+1 -> 46025 | H2: =G2+1 -> 46026
B3: =B2+7 -> 46027 | C3: =B3+1 -> 46028 | D3: =C3+1 -> 46029 | E3: =D3+1 -> 46030 | F3: =E3+1 -> 46031 | G3: =F3+1 -> 46032 | H3: =G3+1 -> 46033
B4: =B3+7 -> 46034 | C4: =B4+1 -> 46035 | D4: =C4+1 -> 46036 | E4: =D4+1 -> 46037 | F4: =E4+1 -> 46038 | G4: =F4+1 -> 46039 | H4: =G4+1 -> 46040
B5: =B4+7 -> 46041 | C5: =B5+1 -> 46042 | D5: =C5+1 -> 46043 | E5: =D5+1 -> 46044 | F5: =E5+1 -> 46045 | G5: =F5+1 -> 46046 | H5: =G5+1 -> 46047
B6: =B5+7 -> 46048 | C6: =B6+1 -> 46049 | D6: =C6+1 -> 46050 | E6: =D6+1 -> 46051 | F6: =E6+1 -> 46052 | G6: =F6+1 -> 46053 | H6: =G6+1 -> 46054
A7: FEB | B7: =B6+7 -> 46055 | C7: =B7+1 -> 46056 | D7: =C7+1 -> 46057 | E7: =D7+1 -> 46058 | F7: =E7+1 -> 46059 | G7: =F7+1 -> 46060 | H7: =G7+1 -> 46061
B8: =B7+7 -> 46062 | C8: =B8+1 -> 46063 | D8: =C8+1 -> 46064 | E8: =D8+1 -> 46065 | F8: =E8+1 -> 46066 | G8: =F8+1 -> 46067 | H8: =G8+1 -> 46068
B9: =B8+7 -> 46069 | C9: =B9+1 -> 46070 | D9: =C9+1 -> 46071 | E9: =D9+1 -> 46072 | F9: =E9+1 -> 46073 | G9: =F9+1 -> 46074 | H9: =G9+1 -> 46075
B10: =B9+7 -> 46076 | C10: =B10+1 -> 46077 | D10: =C10+1 -> 46078 | E10: =D10+1 -> 46079 | F10: =E10+1 -> 46080 | G10: =F10+1 -> 46081 | H10: =G10+1 -> 46082
A11: MAR | B11: =B10+7 -> 46083 | C11: =B11+1 -> 46084 | D11: =C11+1 -> 46085 | E11: =D11+1 -> 46086 | F11: =E11+1 -> 46087 | G11: =F11+1 -> 46088 | H11: =G11+1 -> 46089
B12: =B11+7 -> 46090 | C12: =B12+1 -> 46091 | D12: =C12+1 -> 46092 | E12: =D12+1 -> 46093 | F12: =E12+1 -> 46094 | G12: =F12+1 -> 46095 | H12: =G12+1 -> 46096
B13: =B12+7 -> 46097 | C13: =B13+1 -> 46098 | D13: =C13+1 -> 46099 | E13: =D13+1 -> 46100 | F13: =E13+1 -> 46101 | G13: =F13+1 -> 46102 | H13: =G13+1 -> 46103
B14: =B13+7 -> 46104 | C14: =B14+1 -> 46105 | D14: =C14+1 -> 46106 | E14: =D14+1 -> 46107 | F14: =E14+1 -> 46108 | G14: =F14+1 -> 46109 | H14: =G14+1 -> 46110
A15: APR | B15: =B14+7 -> 46111 | C15: =B15+1 -> 46112 | D15: =C15+1 -> 46113 | E15: =D15+1 -> 46114 | F15: =E15+1 -> 46115 | G15: =F15+1 -> 46116 | H15: =G15+1 -> 46117
B16: =B15+7 -> 46118 | C16: =B16+1 -> 46119 | D16: =C16+1 -> 46120 | E16: =D16+1 -> 46121 | F16: =E16+1 -> 46122 | G16: =F16+1 -> 46123 | H16: =G16+1 -> 46124
B17: =B16+7 -> 46125 | C17: =B17+1 -> 46126 | D17: =C17+1 -> 46127 | E17: =D17+1 -> 46128 | F17: =E17+1 -> 46129 | G17: =F17+1 -> 46130 | H17: =G17+1 -> 46131
B18: =B17+7 -> 46132 | C18: =B18+1 -> 46133 | D18: =C18+1 -> 46134 | E18: =D18+1 -> 46135 | F18: =E18+1 -> 46136 | G18: =F18+1 -> 46137 | H18: =G18+1 -> 46138
B19: =B18+7 -> 46139 | C19: =B19+1 -> 46140 | D19: =C19+1 -> 46141 | E19: =D19+1 -> 46142 | F19: =E19+1 -> 46143 | G19: =F19+1 -> 46144 | H19: =G19+1 -> 46145
A20: MAY | B20: =B19+7 -> 46146 | C20: =B20+1 -> 46147 | D20: =C20+1 -> 46148 | E20: =D20+1 -> 46149 | F20: =E20+1 -> 46150 | G20: =F20+1 -> 46151 | H20: =G20+1 -> 46152
B21: =B20+7 -> 46153 | C21: =B21+1 -> 46154 | D21: =C21+1 -> 46155 | E21: =D21+1 -> 46156 | F21: =E21+1 -> 46157 | G21: =F21+1 -> 46158 | H21: =G21+1 -> 46159
B22: =B21+7 -> 46160 | C22: =B22+1 -> 46161 | D22: =C22+1 -> 46162 | E22: =D22+1 -> 46163 | F22: =E22+1 -> 46164 | G22: =F22+1 -> 46165 | H22: =G22+1 -> 46166
B23: =B22+7 -> 46167 | C23: =B23+1 -> 46168 | D23: =C23+1 -> 46169 | E23: =D23+1 -> 46170 | F23: =E23+1 -> 46171 | G23: =F23+1 -> 46172 | H23: =G23+1 -> 46173
A24: JUN | B24: =B23+7 -> 46174 | C24: =B24+1 -> 46175 | D24: =C24+1 -> 46176 | E24: =D24+1 -> 46177 | F24: =E24+1 -> 46178 | G24: =F24+1 -> 46179 | H24: =G24+1 -> 46180
B25: =B24+7 -> 46181 | C25: =B25+1 -> 46182 | D25: =C25+1 -> 46183 | E25: =D25+1 -> 46184 | F25: =E25+1 -> 46185 | G25: =F25+1 -> 46186 | H25: =G25+1 -> 46187
B26: =B25+7 -> 46188 | C26: =B26+1 -> 46189 | D26: =C26+1 -> 46190 | E26: =D26+1 -> 46191 | F26: =E26+1 -> 46192 | G26: =F26+1 -> 46193 | H26: =G26+1 -> 46194
B27: =B26+7 -> 46195 | C27: =B27+1 -> 46196 | D27: =C27+1 -> 46197 | E27: =D27+1 -> 46198 | F27: =E27+1 -> 46199 | G27: =F27+1 -> 46200 | H27: =G27+1 -> 46201
A28: JUL | B28: =B27+7 -> 46202 | C28: =B28+1 -> 46203 | D28: =C28+1 -> 46204 | E28: =D28+1 -> 46205 | F28: =E28+1 -> 46206 | G28: =F28+1 -> 46207 | H28: =G28+1 -> 46208
B29: =B28+7 -> 46209 | C29: =B29+1 -> 46210 | D29: =C29+1 -> 46211 | E29: =D29+1 -> 46212 | F29: =E29+1 -> 46213 | G29: =F29+1 -> 46214 | H29: =G29+1 -> 46215
B30: =B29+7 -> 46216 | C30: =B30+1 -> 46217 | D30: =C30+1 -> 46218 | E30: =D30+1 -> 46219 | F30: =E30+1 -> 46220 | G30: =F30+1 -> 46221 | H30: =G30+1 -> 46222
B31: =B30+7 -> 46223 | C31: =B31+1 -> 46224 | D31: =C31+1 -> 46225 | E31: =D31+1 -> 46226 | F31: =E31+1 -> 46227 | G31: =F31+1 -> 46228 | H31: =G31+1 -> 46229
B32: =B31+7 -> 46230 | C32: =B32+1 -> 46231 | D32: =C32+1 -> 46232 | E32: =D32+1 -> 46233 | F32: =E32+1 -> 46234 | G32: =F32+1 -> 46235 | H32: =G32+1 -> 46236
A33: AUG | B33: =B32+7 -> 46237 | C33: =B33+1 -> 46238 | D33: =C33+1 -> 46239 | E33: =D33+1 -> 46240 | F33: =E33+1 -> 46241 | G33: =F33+1 -> 46242 | H33: =G33+1 -> 46243
B34: =B33+7 -> 46244 | C34: =B34+1 -> 46245 | D34: =C34+1 -> 46246 | E34: =D34+1 -> 46247 | F34: =E34+1 -> 46248 | G34: =F34+1 -> 46249 | H34: =G34+1 -> 46250
B35: =B34+7 -> 46251 | C35: =B35+1 -> 46252 | D35: =C35+1 -> 46253 | E35: =D35+1 -> 46254 | F35: =E35+1 -> 46255 | G35: =F35+1 -> 46256 | H35: =G35+1 -> 46257
B36: =B35+7 -> 46258 | C36: =B36+1 -> 46259 | D36: =C36+1 -> 46260 | E36: =D36+1 -> 46261 | F36: =E36+1 -> 46262 | G36: =F36+1 -> 46263 | H36: =G36+1 -> 46264
A37: SEP | B37: =B36+7 -> 46265 | C37: =B37+1 -> 46266 | D37: =C37+1 -> 46267 | E37: =D37+1 -> 46268 | F37: =E37+1 -> 46269 | G37: =F37+1 -> 46270 | H37: =G37+1 -> 46271
B38: =B37+7 -> 46272 | C38: =B38+1 -> 46273 | D38: =C38+1 -> 46274 | E38: =D38+1 -> 46275 | F38: =E38+1 -> 46276 | G38: =F38+1 -> 46277 | H38: =G38+1 -> 46278
B39: =B38+7 -> 46279 | C39: =B39+1 -> 46280 | D39: =C39+1 -> 46281 | E39: =D39+1 -> 46282 | F39: =E39+1 -> 46283 | G39: =F39+1 -> 46284 | H39: =G39+1 -> 46285
B40: =B39+7 -> 46286 | C40: =B40+1 -> 46287 | D40: =C40+1 -> 46288 | E40: =D40+1 -> 46289 | F40: =E40+1 -> 46290 | G40: =F40+1 -> 46291 | H40: =G40+1 -> 46292
...

Sheet Admin
A1: Event Holes | B1: Chapter
A2: 9 | B2: Austin
A3: 18 | B3: San Antonio
B4: DFW
B5: Houston
